ERROR 2025-10-22 12:17:45,691 log 1811 6169030656 Internal Server Error: /pilgrims/camera-counter/
Traceback (most recent call last):
  File "/Users/asrafulalamshamrat/Desktop/Work/Dr Wadee/Orange Pi/new_dashboard/venv/lib/python3.9/site-packages/django/core/handlers/exception.py", line 55, in inner
    response = get_response(request)
  File "/Users/asrafulalamshamrat/Desktop/Work/Dr Wadee/Orange Pi/new_dashboard/venv/lib/python3.9/site-packages/django/core/handlers/base.py", line 197, in _get_response
    response = wrapped_callback(request, *callback_args, **callback_kwargs)
  File "/Users/asrafulalamshamrat/Desktop/Work/Dr Wadee/Orange Pi/new_dashboard/venv/lib/python3.9/site-packages/django/views/decorators/csrf.py", line 56, in wrapper_view
    return view_func(*args, **kwargs)
  File "/Users/asrafulalamshamrat/Desktop/Work/Dr Wadee/Orange Pi/new_dashboard/venv/lib/python3.9/site-packages/django/views/generic/base.py", line 105, in view
    return self.dispatch(request, *args, **kwargs)
  File "/Users/asrafulalamshamrat/Desktop/Work/Dr Wadee/Orange Pi/new_dashboard/venv/lib/python3.9/site-packages/django/utils/decorators.py", line 46, in _wrapper
    return bound_method(*args, **kwargs)
  File "/Users/asrafulalamshamrat/Desktop/Work/Dr Wadee/Orange Pi/new_dashboard/venv/lib/python3.9/site-packages/django/views/decorators/csrf.py", line 56, in wrapper_view
    return view_func(*args, **kwargs)
  File "/Users/asrafulalamshamrat/Desktop/Work/Dr Wadee/Orange Pi/new_dashboard/venv/lib/python3.9/site-packages/rest_framework/views.py", line 515, in dispatch
    response = self.handle_exception(exc)
  File "/Users/asrafulalamshamrat/Desktop/Work/Dr Wadee/Orange Pi/new_dashboard/venv/lib/python3.9/site-packages/rest_framework/views.py", line 475, in handle_exception
    self.raise_uncaught_exception(exc)
  File "/Users/asrafulalamshamrat/Desktop/Work/Dr Wadee/Orange Pi/new_dashboard/venv/lib/python3.9/site-packages/rest_framework/views.py", line 486, in raise_uncaught_exception
    raise exc
  File "/Users/asrafulalamshamrat/Desktop/Work/Dr Wadee/Orange Pi/new_dashboard/venv/lib/python3.9/site-packages/rest_framework/views.py", line 512, in dispatch
    response = handler(request, *args, **kwargs)
  File "/Users/asrafulalamshamrat/Desktop/Work/Dr Wadee/Orange Pi/new_dashboard/pilgrims/views.py", line 76, in post
    {"message": "Data processed successfully.", "data": serializer.data},
  File "/Users/asrafulalamshamrat/Desktop/Work/Dr Wadee/Orange Pi/new_dashboard/venv/lib/python3.9/site-packages/rest_framework/serializers.py", line 573, in data
    ret = super().data
  File "/Users/asrafulalamshamrat/Desktop/Work/Dr Wadee/Orange Pi/new_dashboard/venv/lib/python3.9/site-packages/rest_framework/serializers.py", line 251, in data
    self._data = self.to_representation(self.instance)
  File "/Users/asrafulalamshamrat/Desktop/Work/Dr Wadee/Orange Pi/new_dashboard/venv/lib/python3.9/site-packages/rest_framework/serializers.py", line 525, in to_representation
    for field in fields:
  File "/Users/asrafulalamshamrat/Desktop/Work/Dr Wadee/Orange Pi/new_dashboard/venv/lib/python3.9/site-packages/rest_framework/serializers.py", line 386, in _readable_fields
    for field in self.fields.values():
  File "/Users/asrafulalamshamrat/Desktop/Work/Dr Wadee/Orange Pi/new_dashboard/venv/lib/python3.9/site-packages/django/utils/functional.py", line 57, in __get__
    res = instance.__dict__[self.name] = self.func(instance)
  File "/Users/asrafulalamshamrat/Desktop/Work/Dr Wadee/Orange Pi/new_dashboard/venv/lib/python3.9/site-packages/rest_framework/serializers.py", line 374, in fields
    for key, value in self.get_fields().items():
  File "/Users/asrafulalamshamrat/Desktop/Work/Dr Wadee/Orange Pi/new_dashboard/venv/lib/python3.9/site-packages/rest_framework/serializers.py", line 1105, in get_fields
    field_class, field_kwargs = self.build_field(
  File "/Users/asrafulalamshamrat/Desktop/Work/Dr Wadee/Orange Pi/new_dashboard/venv/lib/python3.9/site-packages/rest_framework/serializers.py", line 1251, in build_field
    return self.build_unknown_field(field_name, model_class)
  File "/Users/asrafulalamshamrat/Desktop/Work/Dr Wadee/Orange Pi/new_dashboard/venv/lib/python3.9/site-packages/rest_framework/serializers.py", line 1369, in build_unknown_field
    raise ImproperlyConfigured(
django.core.exceptions.ImproperlyConfigured: Field name `illegal_pilgrim` is not valid for model `Pilgrim` in `pilgrims.serializers.PilgrimSerializer`.
ERROR 2025-10-22 12:17:45,705 basehttp 1811 6169030656 "POST /pilgrims/camera-counter/ HTTP/1.1" 500 145
ERROR 2025-10-26 08:24:34,782 log 2129 6197800960 Internal Server Error: /pilgrims/illegal-pilgrims/1
Traceback (most recent call last):
  File "/Users/asrafulalamshamrat/Desktop/Work/Dr Wadee/Orange Pi/new_dashboard/venv/lib/python3.9/site-packages/django/db/models/fields/__init__.py", line 2053, in get_prep_value
    return int(value)
TypeError: int() argument must be a string, a bytes-like object or a number, not 'builtin_function_or_method'

The above exception was the direct cause of the following exception:

Traceback (most recent call last):
  File "/Users/asrafulalamshamrat/Desktop/Work/Dr Wadee/Orange Pi/new_dashboard/venv/lib/python3.9/site-packages/django/core/handlers/exception.py", line 55, in inner
    response = get_response(request)
  File "/Users/asrafulalamshamrat/Desktop/Work/Dr Wadee/Orange Pi/new_dashboard/venv/lib/python3.9/site-packages/django/core/handlers/base.py", line 197, in _get_response
    response = wrapped_callback(request, *callback_args, **callback_kwargs)
  File "/Users/asrafulalamshamrat/Desktop/Work/Dr Wadee/Orange Pi/new_dashboard/venv/lib/python3.9/site-packages/django/views/decorators/csrf.py", line 56, in wrapper_view
    return view_func(*args, **kwargs)
  File "/Users/asrafulalamshamrat/Desktop/Work/Dr Wadee/Orange Pi/new_dashboard/venv/lib/python3.9/site-packages/django/views/generic/base.py", line 105, in view
    return self.dispatch(request, *args, **kwargs)
  File "/Users/asrafulalamshamrat/Desktop/Work/Dr Wadee/Orange Pi/new_dashboard/venv/lib/python3.9/site-packages/rest_framework/views.py", line 515, in dispatch
    response = self.handle_exception(exc)
  File "/Users/asrafulalamshamrat/Desktop/Work/Dr Wadee/Orange Pi/new_dashboard/venv/lib/python3.9/site-packages/rest_framework/views.py", line 475, in handle_exception
    self.raise_uncaught_exception(exc)
  File "/Users/asrafulalamshamrat/Desktop/Work/Dr Wadee/Orange Pi/new_dashboard/venv/lib/python3.9/site-packages/rest_framework/views.py", line 486, in raise_uncaught_exception
    raise exc
  File "/Users/asrafulalamshamrat/Desktop/Work/Dr Wadee/Orange Pi/new_dashboard/venv/lib/python3.9/site-packages/rest_framework/views.py", line 512, in dispatch
    response = handler(request, *args, **kwargs)
  File "/Users/asrafulalamshamrat/Desktop/Work/Dr Wadee/Orange Pi/new_dashboard/pilgrims/views.py", line 153, in get
    pilgrim = Pilgrim.objects.get(pk=id, illegal_pilgrims__gt=0)
  File "/Users/asrafulalamshamrat/Desktop/Work/Dr Wadee/Orange Pi/new_dashboard/venv/lib/python3.9/site-packages/django/db/models/manager.py", line 87, in manager_method
    return getattr(self.get_queryset(), name)(*args, **kwargs)
  File "/Users/asrafulalamshamrat/Desktop/Work/Dr Wadee/Orange Pi/new_dashboard/venv/lib/python3.9/site-packages/django/db/models/query.py", line 623, in get
    clone = self._chain() if self.query.combinator else self.filter(*args, **kwargs)
  File "/Users/asrafulalamshamrat/Desktop/Work/Dr Wadee/Orange Pi/new_dashboard/venv/lib/python3.9/site-packages/django/db/models/query.py", line 1436, in filter
    return self._filter_or_exclude(False, args, kwargs)
  File "/Users/asrafulalamshamrat/Desktop/Work/Dr Wadee/Orange Pi/new_dashboard/venv/lib/python3.9/site-packages/django/db/models/query.py", line 1454, in _filter_or_exclude
    clone._filter_or_exclude_inplace(negate, args, kwargs)
  File "/Users/asrafulalamshamrat/Desktop/Work/Dr Wadee/Orange Pi/new_dashboard/venv/lib/python3.9/site-packages/django/db/models/query.py", line 1461, in _filter_or_exclude_inplace
    self._query.add_q(Q(*args, **kwargs))
  File "/Users/asrafulalamshamrat/Desktop/Work/Dr Wadee/Orange Pi/new_dashboard/venv/lib/python3.9/site-packages/django/db/models/sql/query.py", line 1546, in add_q
    clause, _ = self._add_q(q_object, self.used_aliases)
  File "/Users/asrafulalamshamrat/Desktop/Work/Dr Wadee/Orange Pi/new_dashboard/venv/lib/python3.9/site-packages/django/db/models/sql/query.py", line 1577, in _add_q
    child_clause, needed_inner = self.build_filter(
  File "/Users/asrafulalamshamrat/Desktop/Work/Dr Wadee/Orange Pi/new_dashboard/venv/lib/python3.9/site-packages/django/db/models/sql/query.py", line 1492, in build_filter
    condition = self.build_lookup(lookups, col, value)
  File "/Users/asrafulalamshamrat/Desktop/Work/Dr Wadee/Orange Pi/new_dashboard/venv/lib/python3.9/site-packages/django/db/models/sql/query.py", line 1319, in build_lookup
    lookup = lookup_class(lhs, rhs)
  File "/Users/asrafulalamshamrat/Desktop/Work/Dr Wadee/Orange Pi/new_dashboard/venv/lib/python3.9/site-packages/django/db/models/lookups.py", line 27, in __init__
    self.rhs = self.get_prep_lookup()
  File "/Users/asrafulalamshamrat/Desktop/Work/Dr Wadee/Orange Pi/new_dashboard/venv/lib/python3.9/site-packages/django/db/models/lookups.py", line 341, in get_prep_lookup
    return super().get_prep_lookup()
  File "/Users/asrafulalamshamrat/Desktop/Work/Dr Wadee/Orange Pi/new_dashboard/venv/lib/python3.9/site-packages/django/db/models/lookups.py", line 85, in get_prep_lookup
    return self.lhs.output_field.get_prep_value(self.rhs)
  File "/Users/asrafulalamshamrat/Desktop/Work/Dr Wadee/Orange Pi/new_dashboard/venv/lib/python3.9/site-packages/django/db/models/fields/__init__.py", line 2055, in get_prep_value
    raise e.__class__(
TypeError: Field 'id' expected a number but got <built-in function id>.
ERROR 2025-10-26 08:24:34,798 basehttp 2129 6197800960 "GET /pilgrims/illegal-pilgrims/1 HTTP/1.1" 500 145
