ERROR 2025-10-22 12:17:45,691 log 1811 6169030656 Internal Server Error: /pilgrims/camera-counter/
Traceback (most recent call last):
  File "/Users/asrafulalamshamrat/Desktop/Work/Dr Wadee/Orange Pi/new_dashboard/venv/lib/python3.9/site-packages/django/core/handlers/exception.py", line 55, in inner
    response = get_response(request)
  File "/Users/asrafulalamshamrat/Desktop/Work/Dr Wadee/Orange Pi/new_dashboard/venv/lib/python3.9/site-packages/django/core/handlers/base.py", line 197, in _get_response
    response = wrapped_callback(request, *callback_args, **callback_kwargs)
  File "/Users/asrafulalamshamrat/Desktop/Work/Dr Wadee/Orange Pi/new_dashboard/venv/lib/python3.9/site-packages/django/views/decorators/csrf.py", line 56, in wrapper_view
    return view_func(*args, **kwargs)
  File "/Users/asrafulalamshamrat/Desktop/Work/Dr Wadee/Orange Pi/new_dashboard/venv/lib/python3.9/site-packages/django/views/generic/base.py", line 105, in view
    return self.dispatch(request, *args, **kwargs)
  File "/Users/asrafulalamshamrat/Desktop/Work/Dr Wadee/Orange Pi/new_dashboard/venv/lib/python3.9/site-packages/django/utils/decorators.py", line 46, in _wrapper
    return bound_method(*args, **kwargs)
  File "/Users/asrafulalamshamrat/Desktop/Work/Dr Wadee/Orange Pi/new_dashboard/venv/lib/python3.9/site-packages/django/views/decorators/csrf.py", line 56, in wrapper_view
    return view_func(*args, **kwargs)
  File "/Users/asrafulalamshamrat/Desktop/Work/Dr Wadee/Orange Pi/new_dashboard/venv/lib/python3.9/site-packages/rest_framework/views.py", line 515, in dispatch
    response = self.handle_exception(exc)
  File "/Users/asrafulalamshamrat/Desktop/Work/Dr Wadee/Orange Pi/new_dashboard/venv/lib/python3.9/site-packages/rest_framework/views.py", line 475, in handle_exception
    self.raise_uncaught_exception(exc)
  File "/Users/asrafulalamshamrat/Desktop/Work/Dr Wadee/Orange Pi/new_dashboard/venv/lib/python3.9/site-packages/rest_framework/views.py", line 486, in raise_uncaught_exception
    raise exc
  File "/Users/asrafulalamshamrat/Desktop/Work/Dr Wadee/Orange Pi/new_dashboard/venv/lib/python3.9/site-packages/rest_framework/views.py", line 512, in dispatch
    response = handler(request, *args, **kwargs)
  File "/Users/asrafulalamshamrat/Desktop/Work/Dr Wadee/Orange Pi/new_dashboard/pilgrims/views.py", line 76, in post
    {"message": "Data processed successfully.", "data": serializer.data},
  File "/Users/asrafulalamshamrat/Desktop/Work/Dr Wadee/Orange Pi/new_dashboard/venv/lib/python3.9/site-packages/rest_framework/serializers.py", line 573, in data
    ret = super().data
  File "/Users/asrafulalamshamrat/Desktop/Work/Dr Wadee/Orange Pi/new_dashboard/venv/lib/python3.9/site-packages/rest_framework/serializers.py", line 251, in data
    self._data = self.to_representation(self.instance)
  File "/Users/asrafulalamshamrat/Desktop/Work/Dr Wadee/Orange Pi/new_dashboard/venv/lib/python3.9/site-packages/rest_framework/serializers.py", line 525, in to_representation
    for field in fields:
  File "/Users/asrafulalamshamrat/Desktop/Work/Dr Wadee/Orange Pi/new_dashboard/venv/lib/python3.9/site-packages/rest_framework/serializers.py", line 386, in _readable_fields
    for field in self.fields.values():
  File "/Users/asrafulalamshamrat/Desktop/Work/Dr Wadee/Orange Pi/new_dashboard/venv/lib/python3.9/site-packages/django/utils/functional.py", line 57, in __get__
    res = instance.__dict__[self.name] = self.func(instance)
  File "/Users/asrafulalamshamrat/Desktop/Work/Dr Wadee/Orange Pi/new_dashboard/venv/lib/python3.9/site-packages/rest_framework/serializers.py", line 374, in fields
    for key, value in self.get_fields().items():
  File "/Users/asrafulalamshamrat/Desktop/Work/Dr Wadee/Orange Pi/new_dashboard/venv/lib/python3.9/site-packages/rest_framework/serializers.py", line 1105, in get_fields
    field_class, field_kwargs = self.build_field(
  File "/Users/asrafulalamshamrat/Desktop/Work/Dr Wadee/Orange Pi/new_dashboard/venv/lib/python3.9/site-packages/rest_framework/serializers.py", line 1251, in build_field
    return self.build_unknown_field(field_name, model_class)
  File "/Users/asrafulalamshamrat/Desktop/Work/Dr Wadee/Orange Pi/new_dashboard/venv/lib/python3.9/site-packages/rest_framework/serializers.py", line 1369, in build_unknown_field
    raise ImproperlyConfigured(
django.core.exceptions.ImproperlyConfigured: Field name `illegal_pilgrim` is not valid for model `Pilgrim` in `pilgrims.serializers.PilgrimSerializer`.
ERROR 2025-10-22 12:17:45,705 basehttp 1811 6169030656 "POST /pilgrims/camera-counter/ HTTP/1.1" 500 145
